[2023-01-17T12:09:50.539+0000] {taskinstance.py:1087} INFO - Dependencies all met for <TaskInstance: sample_data_etl_v4.sample_data_precheck scheduled__2023-01-17T04:00:00+00:00 [queued]>
[2023-01-17T12:09:50.569+0000] {taskinstance.py:1087} INFO - Dependencies all met for <TaskInstance: sample_data_etl_v4.sample_data_precheck scheduled__2023-01-17T04:00:00+00:00 [queued]>
[2023-01-17T12:09:50.718+0000] {taskinstance.py:1283} INFO - 
--------------------------------------------------------------------------------
[2023-01-17T12:09:50.718+0000] {taskinstance.py:1284} INFO - Starting attempt 2 of 2
[2023-01-17T12:09:50.719+0000] {taskinstance.py:1285} INFO - 
--------------------------------------------------------------------------------
[2023-01-17T12:09:52.862+0000] {taskinstance.py:1304} INFO - Executing <Task(MsSqlOperator): sample_data_precheck> on 2023-01-17 04:00:00+00:00
[2023-01-17T12:09:52.876+0000] {standard_task_runner.py:55} INFO - Started process 4070 to run task
[2023-01-17T12:09:52.885+0000] {standard_task_runner.py:82} INFO - Running: ['***', 'tasks', 'run', 'sample_data_etl_v4', 'sample_data_precheck', 'scheduled__2023-01-17T04:00:00+00:00', '--job-id', '456', '--raw', '--subdir', 'DAGS_FOLDER/test_table_insert.py', '--cfg-path', '/tmp/tmpx2jc12g0']
[2023-01-17T12:09:54.059+0000] {standard_task_runner.py:83} INFO - Job 456: Subtask sample_data_precheck
[2023-01-17T12:10:17.023+0000] {task_command.py:389} INFO - Running <TaskInstance: sample_data_etl_v4.sample_data_precheck scheduled__2023-01-17T04:00:00+00:00 [running]> on host c7f1bfaaf748
[2023-01-17T12:10:17.839+0000] {taskinstance.py:1513} INFO - Exporting the following env vars:
AIRFLOW_CTX_DAG_EMAIL=StepanovLM@eurosib.biz
AIRFLOW_CTX_DAG_OWNER=***
AIRFLOW_CTX_DAG_ID=sample_data_etl_v4
AIRFLOW_CTX_TASK_ID=sample_data_precheck
AIRFLOW_CTX_EXECUTION_DATE=2023-01-17T04:00:00+00:00
AIRFLOW_CTX_TRY_NUMBER=2
AIRFLOW_CTX_DAG_RUN_ID=scheduled__2023-01-17T04:00:00+00:00
[2023-01-17T12:10:17.840+0000] {sql.py:253} INFO - Executing: select getDate() as nowdate
[2023-01-17T12:10:17.849+0000] {base.py:73} INFO - Using connection ID 'tsxdvp' for task execution.
[2023-01-17T12:10:18.131+0000] {base.py:73} INFO - Using connection ID 'tsxdvp' for task execution.
[2023-01-17T12:10:23.402+0000] {sql.py:364} INFO - Running statement: select getDate() as nowdate, parameters: None
[2023-01-17T12:10:23.424+0000] {taskinstance.py:1772} ERROR - Task failed with exception
Traceback (most recent call last):
  File "/home/airflow/.local/lib/python3.7/site-packages/airflow/utils/session.py", line 72, in wrapper
    return func(*args, **kwargs)
  File "/home/airflow/.local/lib/python3.7/site-packages/airflow/models/taskinstance.py", line 2301, in xcom_push
    session=session,
  File "/home/airflow/.local/lib/python3.7/site-packages/airflow/utils/session.py", line 72, in wrapper
    return func(*args, **kwargs)
  File "/home/airflow/.local/lib/python3.7/site-packages/airflow/models/xcom.py", line 240, in set
    map_index=map_index,
  File "/home/airflow/.local/lib/python3.7/site-packages/airflow/models/xcom.py", line 627, in serialize_value
    return json.dumps(value, cls=XComEncoder).encode("UTF-8")
  File "/usr/local/lib/python3.7/json/__init__.py", line 238, in dumps
    **kw).encode(obj)
  File "/home/airflow/.local/lib/python3.7/site-packages/airflow/utils/json.py", line 176, in encode
    return super().encode(o)
  File "/usr/local/lib/python3.7/json/encoder.py", line 199, in encode
    chunks = self.iterencode(o, _one_shot=True)
  File "/usr/local/lib/python3.7/json/encoder.py", line 257, in iterencode
    return _iterencode(o, 0)
  File "/home/airflow/.local/lib/python3.7/site-packages/airflow/utils/json.py", line 153, in default
    CLASSNAME: o.__module__ + "." + o.__class__.__qualname__,
AttributeError: 'datetime.datetime' object has no attribute '__module__'
[2023-01-17T12:10:24.471+0000] {taskinstance.py:1327} INFO - Marking task as FAILED. dag_id=sample_data_etl_v4, task_id=sample_data_precheck, execution_date=20230117T040000, start_date=20230117T120950, end_date=20230117T121024
[2023-01-17T12:10:24.795+0000] {logging_mixin.py:137} WARNING - /home/***/.local/lib/python3.7/site-packages/***/utils/email.py:120 RemovedInAirflow3Warning: Fetching SMTP credentials from configuration variables will be deprecated in a future release. Please set credentials using a connection instead.
[2023-01-17T12:10:24.855+0000] {configuration.py:635} WARNING - section/key [smtp/smtp_user] not found in config
[2023-01-17T12:10:24.873+0000] {email.py:229} INFO - Email alerting: attempt 1
[2023-01-17T12:10:24.903+0000] {configuration.py:635} WARNING - section/key [smtp/smtp_user] not found in config
[2023-01-17T12:10:24.911+0000] {email.py:229} INFO - Email alerting: attempt 1
[2023-01-17T12:10:24.913+0000] {taskinstance.py:1835} ERROR - Failed to send email to: ['StepanovLM@eurosib.biz']
Traceback (most recent call last):
  File "/home/airflow/.local/lib/python3.7/site-packages/airflow/models/taskinstance.py", line 1378, in _run_raw_task
    self._execute_task_with_callbacks(context, test_mode)
  File "/home/airflow/.local/lib/python3.7/site-packages/airflow/models/taskinstance.py", line 1524, in _execute_task_with_callbacks
    result = self._execute_task(context, task_orig)
  File "/home/airflow/.local/lib/python3.7/site-packages/airflow/models/taskinstance.py", line 1592, in _execute_task
    self.xcom_push(key=XCOM_RETURN_KEY, value=xcom_value, session=session)
  File "/home/airflow/.local/lib/python3.7/site-packages/airflow/utils/session.py", line 72, in wrapper
    return func(*args, **kwargs)
  File "/home/airflow/.local/lib/python3.7/site-packages/airflow/models/taskinstance.py", line 2301, in xcom_push
    session=session,
  File "/home/airflow/.local/lib/python3.7/site-packages/airflow/utils/session.py", line 72, in wrapper
    return func(*args, **kwargs)
  File "/home/airflow/.local/lib/python3.7/site-packages/airflow/models/xcom.py", line 240, in set
    map_index=map_index,
  File "/home/airflow/.local/lib/python3.7/site-packages/airflow/models/xcom.py", line 627, in serialize_value
    return json.dumps(value, cls=XComEncoder).encode("UTF-8")
  File "/usr/local/lib/python3.7/json/__init__.py", line 238, in dumps
    **kw).encode(obj)
  File "/home/airflow/.local/lib/python3.7/site-packages/airflow/utils/json.py", line 176, in encode
    return super().encode(o)
  File "/usr/local/lib/python3.7/json/encoder.py", line 199, in encode
    chunks = self.iterencode(o, _one_shot=True)
  File "/usr/local/lib/python3.7/json/encoder.py", line 257, in iterencode
    return _iterencode(o, 0)
  File "/home/airflow/.local/lib/python3.7/site-packages/airflow/utils/json.py", line 153, in default
    CLASSNAME: o.__module__ + "." + o.__class__.__qualname__,
AttributeError: 'datetime.datetime' object has no attribute '__module__'

During handling of the above exception, another exception occurred:

Traceback (most recent call last):
  File "/home/airflow/.local/lib/python3.7/site-packages/airflow/models/taskinstance.py", line 2235, in email_alert
    send_email(task.email, subject, html_content)
  File "/home/airflow/.local/lib/python3.7/site-packages/airflow/utils/email.py", line 72, in send_email
    **kwargs,
  File "/home/airflow/.local/lib/python3.7/site-packages/airflow/utils/email.py", line 120, in send_email_smtp
    send_mime_email(e_from=mail_from, e_to=recipients, mime_msg=msg, conn_id=conn_id, dryrun=dryrun)
  File "/home/airflow/.local/lib/python3.7/site-packages/airflow/utils/email.py", line 231, in send_mime_email
    smtp_conn = _get_smtp_connection(smtp_host, smtp_port, smtp_timeout, smtp_ssl)
  File "/home/airflow/.local/lib/python3.7/site-packages/airflow/utils/email.py", line 265, in _get_smtp_connection
    else smtplib.SMTP(host=host, port=port, timeout=timeout)
  File "/usr/local/lib/python3.7/smtplib.py", line 251, in __init__
    (code, msg) = self.connect(host, port)
  File "/usr/local/lib/python3.7/smtplib.py", line 336, in connect
    self.sock = self._get_socket(host, port, self.timeout)
  File "/usr/local/lib/python3.7/smtplib.py", line 307, in _get_socket
    self.source_address)
  File "/usr/local/lib/python3.7/socket.py", line 728, in create_connection
    raise err
  File "/usr/local/lib/python3.7/socket.py", line 716, in create_connection
    sock.connect(sa)
OSError: [Errno 99] Cannot assign requested address

During handling of the above exception, another exception occurred:

Traceback (most recent call last):
  File "/home/airflow/.local/lib/python3.7/site-packages/airflow/models/taskinstance.py", line 1833, in handle_failure
    self.email_alert(error, task)
  File "/home/airflow/.local/lib/python3.7/site-packages/airflow/models/taskinstance.py", line 2237, in email_alert
    send_email(task.email, subject, html_content_err)
  File "/home/airflow/.local/lib/python3.7/site-packages/airflow/utils/email.py", line 72, in send_email
    **kwargs,
  File "/home/airflow/.local/lib/python3.7/site-packages/airflow/utils/email.py", line 120, in send_email_smtp
    send_mime_email(e_from=mail_from, e_to=recipients, mime_msg=msg, conn_id=conn_id, dryrun=dryrun)
  File "/home/airflow/.local/lib/python3.7/site-packages/airflow/utils/email.py", line 231, in send_mime_email
    smtp_conn = _get_smtp_connection(smtp_host, smtp_port, smtp_timeout, smtp_ssl)
  File "/home/airflow/.local/lib/python3.7/site-packages/airflow/utils/email.py", line 265, in _get_smtp_connection
    else smtplib.SMTP(host=host, port=port, timeout=timeout)
  File "/usr/local/lib/python3.7/smtplib.py", line 251, in __init__
    (code, msg) = self.connect(host, port)
  File "/usr/local/lib/python3.7/smtplib.py", line 336, in connect
    self.sock = self._get_socket(host, port, self.timeout)
  File "/usr/local/lib/python3.7/smtplib.py", line 307, in _get_socket
    self.source_address)
  File "/usr/local/lib/python3.7/socket.py", line 728, in create_connection
    raise err
  File "/usr/local/lib/python3.7/socket.py", line 716, in create_connection
    sock.connect(sa)
OSError: [Errno 99] Cannot assign requested address
[2023-01-17T12:10:57.155+0000] {standard_task_runner.py:105} ERROR - Failed to execute job 456 for task sample_data_precheck ('datetime.datetime' object has no attribute '__module__'; 4070)
[2023-01-17T12:10:57.254+0000] {local_task_job.py:159} INFO - Task exited with return code 1
[2023-01-17T12:10:57.980+0000] {taskinstance.py:2582} INFO - 0 downstream tasks scheduled from follow-on schedule check
