[2023-01-17T11:51:17.492+0000] {taskinstance.py:1087} INFO - Dependencies all met for <TaskInstance: sample_data_etl_v3.sample_data_precheck scheduled__2023-01-17T08:00:00+00:00 [queued]>
[2023-01-17T11:51:17.501+0000] {taskinstance.py:1087} INFO - Dependencies all met for <TaskInstance: sample_data_etl_v3.sample_data_precheck scheduled__2023-01-17T08:00:00+00:00 [queued]>
[2023-01-17T11:51:17.502+0000] {taskinstance.py:1283} INFO - 
--------------------------------------------------------------------------------
[2023-01-17T11:51:17.502+0000] {taskinstance.py:1284} INFO - Starting attempt 1 of 2
[2023-01-17T11:51:17.593+0000] {taskinstance.py:1285} INFO - 
--------------------------------------------------------------------------------
[2023-01-17T11:51:18.988+0000] {taskinstance.py:1304} INFO - Executing <Task(MsSqlOperator): sample_data_precheck> on 2023-01-17 08:00:00+00:00
[2023-01-17T11:51:18.993+0000] {standard_task_runner.py:55} INFO - Started process 2187 to run task
[2023-01-17T11:51:18.996+0000] {standard_task_runner.py:82} INFO - Running: ['***', 'tasks', 'run', 'sample_data_etl_v3', 'sample_data_precheck', 'scheduled__2023-01-17T08:00:00+00:00', '--job-id', '426', '--raw', '--subdir', 'DAGS_FOLDER/test_table_insert.py', '--cfg-path', '/tmp/tmpj3d7hel3']
[2023-01-17T11:51:18.998+0000] {standard_task_runner.py:83} INFO - Job 426: Subtask sample_data_precheck
[2023-01-17T11:51:22.069+0000] {task_command.py:389} INFO - Running <TaskInstance: sample_data_etl_v3.sample_data_precheck scheduled__2023-01-17T08:00:00+00:00 [running]> on host c7f1bfaaf748
[2023-01-17T11:51:24.530+0000] {taskinstance.py:1513} INFO - Exporting the following env vars:
AIRFLOW_CTX_DAG_EMAIL=StepanovLM@eurosib.biz
AIRFLOW_CTX_DAG_OWNER=***
AIRFLOW_CTX_DAG_ID=sample_data_etl_v3
AIRFLOW_CTX_TASK_ID=sample_data_precheck
AIRFLOW_CTX_EXECUTION_DATE=2023-01-17T08:00:00+00:00
AIRFLOW_CTX_TRY_NUMBER=1
AIRFLOW_CTX_DAG_RUN_ID=scheduled__2023-01-17T08:00:00+00:00
[2023-01-17T11:51:24.531+0000] {sql.py:253} INFO - Executing: use CarInfo go select getDate() as nowdate
[2023-01-17T11:51:24.539+0000] {base.py:73} INFO - Using connection ID 'tsxdvp' for task execution.
[2023-01-17T11:51:24.787+0000] {base.py:73} INFO - Using connection ID 'tsxdvp' for task execution.
[2023-01-17T11:52:24.805+0000] {taskinstance.py:1772} ERROR - Task failed with exception
Traceback (most recent call last):
  File "src/pymssql/_pymssql.pyx", line 647, in pymssql._pymssql.connect
  File "src/pymssql/_mssql.pyx", line 2109, in pymssql._mssql.connect
  File "src/pymssql/_mssql.pyx", line 701, in pymssql._mssql.MSSQLConnection.__init__
  File "src/pymssql/_mssql.pyx", line 1818, in pymssql._mssql.maybe_raise_MSSQLDatabaseException
  File "src/pymssql/_mssql.pyx", line 1835, in pymssql._mssql.raise_MSSQLDatabaseException
pymssql._mssql.MSSQLDatabaseException: (20009, b'DB-Lib error message 20009, severity 9:\nUnable to connect: Adaptive Server is unavailable or does not exist (172.30.6.32)\nNet-Lib error during Connection timed out (110)\nDB-Lib error message 20009, severity 9:\nUnable to connect: Adaptive Server is unavailable or does not exist (172.30.6.32)\nNet-Lib error during Connection timed out (110)\n')

During handling of the above exception, another exception occurred:

Traceback (most recent call last):
  File "/home/airflow/.local/lib/python3.7/site-packages/airflow/providers/common/sql/operators/sql.py", line 261, in execute
    return_last=self.return_last,
  File "/home/airflow/.local/lib/python3.7/site-packages/airflow/providers/common/sql/hooks/sql.py", line 331, in run
    with closing(self.get_conn()) as conn:
  File "/home/airflow/.local/lib/python3.7/site-packages/airflow/providers/microsoft/mssql/hooks/mssql.py", line 102, in get_conn
    port=conn.port,
  File "src/pymssql/_pymssql.pyx", line 653, in pymssql._pymssql.connect
pymssql._pymssql.OperationalError: (20009, b'DB-Lib error message 20009, severity 9:\nUnable to connect: Adaptive Server is unavailable or does not exist (172.30.6.32)\nNet-Lib error during Connection timed out (110)\nDB-Lib error message 20009, severity 9:\nUnable to connect: Adaptive Server is unavailable or does not exist (172.30.6.32)\nNet-Lib error during Connection timed out (110)\n')
[2023-01-17T11:52:24.814+0000] {taskinstance.py:1327} INFO - Marking task as UP_FOR_RETRY. dag_id=sample_data_etl_v3, task_id=sample_data_precheck, execution_date=20230117T080000, start_date=20230117T115117, end_date=20230117T115224
[2023-01-17T11:52:27.143+0000] {standard_task_runner.py:105} ERROR - Failed to execute job 426 for task sample_data_precheck ((20009, b'DB-Lib error message 20009, severity 9:\nUnable to connect: Adaptive Server is unavailable or does not exist (172.30.6.32)\nNet-Lib error during Connection timed out (110)\nDB-Lib error message 20009, severity 9:\nUnable to connect: Adaptive Server is unavailable or does not exist (172.30.6.32)\nNet-Lib error during Connection timed out (110)\n'); 2187)
[2023-01-17T11:52:28.938+0000] {local_task_job.py:159} INFO - Task exited with return code 1
[2023-01-17T11:52:29.087+0000] {taskinstance.py:2582} INFO - 0 downstream tasks scheduled from follow-on schedule check
