[2023-01-18T08:07:15.230+0000] {taskinstance.py:1087} INFO - Dependencies all met for <TaskInstance: sample_data_etl_v4.sample_data_precheck scheduled__2023-01-18T06:00:00+00:00 [queued]>
[2023-01-18T08:07:15.242+0000] {taskinstance.py:1087} INFO - Dependencies all met for <TaskInstance: sample_data_etl_v4.sample_data_precheck scheduled__2023-01-18T06:00:00+00:00 [queued]>
[2023-01-18T08:07:15.242+0000] {taskinstance.py:1283} INFO - 
--------------------------------------------------------------------------------
[2023-01-18T08:07:15.243+0000] {taskinstance.py:1284} INFO - Starting attempt 1 of 2
[2023-01-18T08:07:15.323+0000] {taskinstance.py:1285} INFO - 
--------------------------------------------------------------------------------
[2023-01-18T08:07:39.436+0000] {taskinstance.py:1304} INFO - Executing <Task(MsSqlOperator): sample_data_precheck> on 2023-01-18 06:00:00+00:00
[2023-01-18T08:07:39.443+0000] {standard_task_runner.py:55} INFO - Started process 1041 to run task
[2023-01-18T08:07:39.447+0000] {standard_task_runner.py:82} INFO - Running: ['***', 'tasks', 'run', 'sample_data_etl_v4', 'sample_data_precheck', 'scheduled__2023-01-18T06:00:00+00:00', '--job-id', '476', '--raw', '--subdir', 'DAGS_FOLDER/test_table_insert.py', '--cfg-path', '/tmp/tmps7g65v1i']
[2023-01-18T08:07:39.457+0000] {standard_task_runner.py:83} INFO - Job 476: Subtask sample_data_precheck
[2023-01-18T08:08:21.146+0000] {task_command.py:389} INFO - Running <TaskInstance: sample_data_etl_v4.sample_data_precheck scheduled__2023-01-18T06:00:00+00:00 [running]> on host c7f1bfaaf748
[2023-01-18T08:08:23.216+0000] {taskinstance.py:1513} INFO - Exporting the following env vars:
AIRFLOW_CTX_DAG_EMAIL=StepanovLM@eurosib.biz
AIRFLOW_CTX_DAG_OWNER=***
AIRFLOW_CTX_DAG_ID=sample_data_etl_v4
AIRFLOW_CTX_TASK_ID=sample_data_precheck
AIRFLOW_CTX_EXECUTION_DATE=2023-01-18T06:00:00+00:00
AIRFLOW_CTX_TRY_NUMBER=1
AIRFLOW_CTX_DAG_RUN_ID=scheduled__2023-01-18T06:00:00+00:00
[2023-01-18T08:08:23.223+0000] {sql.py:253} INFO - Executing: select getDate() as nowdate
[2023-01-18T08:08:23.232+0000] {base.py:73} INFO - Using connection ID 'tsxdvp' for task execution.
[2023-01-18T08:08:23.646+0000] {base.py:73} INFO - Using connection ID 'tsxdvp' for task execution.
[2023-01-18T08:08:33.103+0000] {local_task_job.py:224} WARNING - State of this instance has been externally set to queued. Terminating instance.
[2023-01-18T08:08:33.108+0000] {process_utils.py:133} INFO - Sending Signals.SIGTERM to group 1041. PIDs of all processes in the group: [1041]
[2023-01-18T08:08:33.109+0000] {process_utils.py:84} INFO - Sending the signal Signals.SIGTERM to group 1041
[2023-01-18T08:09:19.272+0000] {taskinstance.py:1483} ERROR - Received SIGTERM. Terminating subprocesses.
[2023-01-18T08:09:19.286+0000] {taskinstance.py:1772} ERROR - Task failed with exception
Traceback (most recent call last):
  File "/home/airflow/.local/lib/python3.7/site-packages/airflow/providers/common/sql/operators/sql.py", line 261, in execute
    return_last=self.return_last,
  File "/home/airflow/.local/lib/python3.7/site-packages/airflow/providers/common/sql/hooks/sql.py", line 331, in run
    with closing(self.get_conn()) as conn:
  File "/home/airflow/.local/lib/python3.7/site-packages/airflow/providers/microsoft/mssql/hooks/mssql.py", line 102, in get_conn
    port=conn.port,
  File "/home/airflow/.local/lib/python3.7/site-packages/airflow/models/taskinstance.py", line 1485, in signal_handler
    raise AirflowException("Task received SIGTERM signal")
airflow.exceptions.AirflowException: Task received SIGTERM signal
[2023-01-18T08:09:19.290+0000] {taskinstance.py:1327} INFO - Marking task as FAILED. dag_id=sample_data_etl_v4, task_id=sample_data_precheck, execution_date=20230118T060000, start_date=20230118T080833, end_date=20230118T080919
[2023-01-18T08:09:19.868+0000] {logging_mixin.py:137} WARNING - /home/***/.local/lib/python3.7/site-packages/***/utils/email.py:120 RemovedInAirflow3Warning: Fetching SMTP credentials from configuration variables will be deprecated in a future release. Please set credentials using a connection instead.
[2023-01-18T08:09:20.150+0000] {configuration.py:635} WARNING - section/key [smtp/smtp_user] not found in config
[2023-01-18T08:09:20.151+0000] {email.py:229} INFO - Email alerting: attempt 1
[2023-01-18T08:09:20.159+0000] {configuration.py:635} WARNING - section/key [smtp/smtp_user] not found in config
[2023-01-18T08:09:20.160+0000] {email.py:229} INFO - Email alerting: attempt 1
[2023-01-18T08:09:20.161+0000] {taskinstance.py:1835} ERROR - Failed to send email to: ['StepanovLM@eurosib.biz']
Traceback (most recent call last):
  File "/home/airflow/.local/lib/python3.7/site-packages/airflow/models/taskinstance.py", line 1378, in _run_raw_task
    self._execute_task_with_callbacks(context, test_mode)
  File "/home/airflow/.local/lib/python3.7/site-packages/airflow/models/taskinstance.py", line 1524, in _execute_task_with_callbacks
    result = self._execute_task(context, task_orig)
  File "/home/airflow/.local/lib/python3.7/site-packages/airflow/models/taskinstance.py", line 1585, in _execute_task
    result = execute_callable(context=context)
  File "/home/airflow/.local/lib/python3.7/site-packages/airflow/providers/common/sql/operators/sql.py", line 261, in execute
    return_last=self.return_last,
  File "/home/airflow/.local/lib/python3.7/site-packages/airflow/providers/common/sql/hooks/sql.py", line 331, in run
    with closing(self.get_conn()) as conn:
  File "/home/airflow/.local/lib/python3.7/site-packages/airflow/providers/microsoft/mssql/hooks/mssql.py", line 102, in get_conn
    port=conn.port,
  File "/home/airflow/.local/lib/python3.7/site-packages/airflow/models/taskinstance.py", line 1485, in signal_handler
    raise AirflowException("Task received SIGTERM signal")
airflow.exceptions.AirflowException: Task received SIGTERM signal

During handling of the above exception, another exception occurred:

Traceback (most recent call last):
  File "/home/airflow/.local/lib/python3.7/site-packages/airflow/models/taskinstance.py", line 2235, in email_alert
    send_email(task.email, subject, html_content)
  File "/home/airflow/.local/lib/python3.7/site-packages/airflow/utils/email.py", line 72, in send_email
    **kwargs,
  File "/home/airflow/.local/lib/python3.7/site-packages/airflow/utils/email.py", line 120, in send_email_smtp
    send_mime_email(e_from=mail_from, e_to=recipients, mime_msg=msg, conn_id=conn_id, dryrun=dryrun)
  File "/home/airflow/.local/lib/python3.7/site-packages/airflow/utils/email.py", line 231, in send_mime_email
    smtp_conn = _get_smtp_connection(smtp_host, smtp_port, smtp_timeout, smtp_ssl)
  File "/home/airflow/.local/lib/python3.7/site-packages/airflow/utils/email.py", line 265, in _get_smtp_connection
    else smtplib.SMTP(host=host, port=port, timeout=timeout)
  File "/usr/local/lib/python3.7/smtplib.py", line 251, in __init__
    (code, msg) = self.connect(host, port)
  File "/usr/local/lib/python3.7/smtplib.py", line 336, in connect
    self.sock = self._get_socket(host, port, self.timeout)
  File "/usr/local/lib/python3.7/smtplib.py", line 307, in _get_socket
    self.source_address)
  File "/usr/local/lib/python3.7/socket.py", line 728, in create_connection
    raise err
  File "/usr/local/lib/python3.7/socket.py", line 716, in create_connection
    sock.connect(sa)
OSError: [Errno 99] Cannot assign requested address

During handling of the above exception, another exception occurred:

Traceback (most recent call last):
  File "/home/airflow/.local/lib/python3.7/site-packages/airflow/models/taskinstance.py", line 1833, in handle_failure
    self.email_alert(error, task)
  File "/home/airflow/.local/lib/python3.7/site-packages/airflow/models/taskinstance.py", line 2237, in email_alert
    send_email(task.email, subject, html_content_err)
  File "/home/airflow/.local/lib/python3.7/site-packages/airflow/utils/email.py", line 72, in send_email
    **kwargs,
  File "/home/airflow/.local/lib/python3.7/site-packages/airflow/utils/email.py", line 120, in send_email_smtp
    send_mime_email(e_from=mail_from, e_to=recipients, mime_msg=msg, conn_id=conn_id, dryrun=dryrun)
  File "/home/airflow/.local/lib/python3.7/site-packages/airflow/utils/email.py", line 231, in send_mime_email
    smtp_conn = _get_smtp_connection(smtp_host, smtp_port, smtp_timeout, smtp_ssl)
  File "/home/airflow/.local/lib/python3.7/site-packages/airflow/utils/email.py", line 265, in _get_smtp_connection
    else smtplib.SMTP(host=host, port=port, timeout=timeout)
  File "/usr/local/lib/python3.7/smtplib.py", line 251, in __init__
    (code, msg) = self.connect(host, port)
  File "/usr/local/lib/python3.7/smtplib.py", line 336, in connect
    self.sock = self._get_socket(host, port, self.timeout)
  File "/usr/local/lib/python3.7/smtplib.py", line 307, in _get_socket
    self.source_address)
  File "/usr/local/lib/python3.7/socket.py", line 728, in create_connection
    raise err
  File "/usr/local/lib/python3.7/socket.py", line 716, in create_connection
    sock.connect(sa)
OSError: [Errno 99] Cannot assign requested address
[2023-01-18T08:09:21.580+0000] {standard_task_runner.py:105} ERROR - Failed to execute job 476 for task sample_data_precheck (Task received SIGTERM signal; 1041)
[2023-01-18T08:09:23.319+0000] {process_utils.py:79} INFO - Process psutil.Process(pid=1041, status='terminated', exitcode=1, started='08:07:38') (1041) terminated with exit code 1
