[2023-01-17T11:49:07.218+0000] {taskinstance.py:1087} INFO - Dependencies all met for <TaskInstance: sample_data_etl_v3.sample_data_precheck scheduled__2023-01-17T02:00:00+00:00 [queued]>
[2023-01-17T11:49:07.229+0000] {taskinstance.py:1087} INFO - Dependencies all met for <TaskInstance: sample_data_etl_v3.sample_data_precheck scheduled__2023-01-17T02:00:00+00:00 [queued]>
[2023-01-17T11:49:07.229+0000] {taskinstance.py:1283} INFO - 
--------------------------------------------------------------------------------
[2023-01-17T11:49:07.230+0000] {taskinstance.py:1284} INFO - Starting attempt 1 of 2
[2023-01-17T11:49:07.237+0000] {taskinstance.py:1285} INFO - 
--------------------------------------------------------------------------------
[2023-01-17T11:49:24.038+0000] {taskinstance.py:1304} INFO - Executing <Task(MsSqlOperator): sample_data_precheck> on 2023-01-17 02:00:00+00:00
[2023-01-17T11:49:24.204+0000] {standard_task_runner.py:55} INFO - Started process 2097 to run task
[2023-01-17T11:49:24.208+0000] {standard_task_runner.py:82} INFO - Running: ['***', 'tasks', 'run', 'sample_data_etl_v3', 'sample_data_precheck', 'scheduled__2023-01-17T02:00:00+00:00', '--job-id', '421', '--raw', '--subdir', 'DAGS_FOLDER/test_table_insert.py', '--cfg-path', '/tmp/tmpxup9ffjm']
[2023-01-17T11:49:24.262+0000] {standard_task_runner.py:83} INFO - Job 421: Subtask sample_data_precheck
[2023-01-17T11:49:24.717+0000] {task_command.py:389} INFO - Running <TaskInstance: sample_data_etl_v3.sample_data_precheck scheduled__2023-01-17T02:00:00+00:00 [running]> on host c7f1bfaaf748
[2023-01-17T11:49:25.609+0000] {taskinstance.py:1513} INFO - Exporting the following env vars:
AIRFLOW_CTX_DAG_EMAIL=StepanovLM@eurosib.biz
AIRFLOW_CTX_DAG_OWNER=***
AIRFLOW_CTX_DAG_ID=sample_data_etl_v3
AIRFLOW_CTX_TASK_ID=sample_data_precheck
AIRFLOW_CTX_EXECUTION_DATE=2023-01-17T02:00:00+00:00
AIRFLOW_CTX_TRY_NUMBER=1
AIRFLOW_CTX_DAG_RUN_ID=scheduled__2023-01-17T02:00:00+00:00
[2023-01-17T11:49:25.611+0000] {sql.py:253} INFO - Executing: use CarInfo go select getDate() as nowdate
[2023-01-17T11:49:25.622+0000] {base.py:73} INFO - Using connection ID 'tsxdvp' for task execution.
[2023-01-17T11:50:05.510+0000] {base.py:73} INFO - Using connection ID 'tsxdvp' for task execution.
[2023-01-17T11:50:15.625+0000] {taskinstance.py:1772} ERROR - Task failed with exception
Traceback (most recent call last):
  File "src/pymssql/_pymssql.pyx", line 647, in pymssql._pymssql.connect
  File "src/pymssql/_mssql.pyx", line 2109, in pymssql._mssql.connect
  File "src/pymssql/_mssql.pyx", line 701, in pymssql._mssql.MSSQLConnection.__init__
  File "src/pymssql/_mssql.pyx", line 1818, in pymssql._mssql.maybe_raise_MSSQLDatabaseException
  File "src/pymssql/_mssql.pyx", line 1835, in pymssql._mssql.raise_MSSQLDatabaseException
pymssql._mssql.MSSQLDatabaseException: (20009, b'DB-Lib error message 20009, severity 9:\nUnable to connect: Adaptive Server is unavailable or does not exist (172.30.6.32)\nNet-Lib error during No route to host (113)\nDB-Lib error message 20009, severity 9:\nUnable to connect: Adaptive Server is unavailable or does not exist (172.30.6.32)\nNet-Lib error during No route to host (113)\n')

During handling of the above exception, another exception occurred:

Traceback (most recent call last):
  File "/home/airflow/.local/lib/python3.7/site-packages/airflow/providers/common/sql/operators/sql.py", line 261, in execute
    return_last=self.return_last,
  File "/home/airflow/.local/lib/python3.7/site-packages/airflow/providers/common/sql/hooks/sql.py", line 331, in run
    with closing(self.get_conn()) as conn:
  File "/home/airflow/.local/lib/python3.7/site-packages/airflow/providers/microsoft/mssql/hooks/mssql.py", line 102, in get_conn
    port=conn.port,
  File "src/pymssql/_pymssql.pyx", line 653, in pymssql._pymssql.connect
pymssql._pymssql.OperationalError: (20009, b'DB-Lib error message 20009, severity 9:\nUnable to connect: Adaptive Server is unavailable or does not exist (172.30.6.32)\nNet-Lib error during No route to host (113)\nDB-Lib error message 20009, severity 9:\nUnable to connect: Adaptive Server is unavailable or does not exist (172.30.6.32)\nNet-Lib error during No route to host (113)\n')
[2023-01-17T11:50:28.620+0000] {taskinstance.py:1327} INFO - Marking task as UP_FOR_RETRY. dag_id=sample_data_etl_v3, task_id=sample_data_precheck, execution_date=20230117T020000, start_date=20230117T114907, end_date=20230117T115028
[2023-01-17T11:50:35.751+0000] {standard_task_runner.py:105} ERROR - Failed to execute job 421 for task sample_data_precheck ((20009, b'DB-Lib error message 20009, severity 9:\nUnable to connect: Adaptive Server is unavailable or does not exist (172.30.6.32)\nNet-Lib error during No route to host (113)\nDB-Lib error message 20009, severity 9:\nUnable to connect: Adaptive Server is unavailable or does not exist (172.30.6.32)\nNet-Lib error during No route to host (113)\n'); 2097)
[2023-01-17T11:50:42.243+0000] {local_task_job.py:224} WARNING - State of this instance has been externally set to up_for_retry. Terminating instance.
[2023-01-17T11:50:52.285+0000] {process_utils.py:133} INFO - Sending Signals.SIGTERM to group 2097. PIDs of all processes in the group: [2097]
[2023-01-17T11:50:58.897+0000] {process_utils.py:84} INFO - Sending the signal Signals.SIGTERM to group 2097
[2023-01-17T11:51:02.026+0000] {process_utils.py:79} INFO - Process psutil.Process(pid=2097, status='terminated', exitcode=1, started='11:49:24') (2097) terminated with exit code 1
