[2023-01-17T11:55:47.095+0000] {taskinstance.py:1087} INFO - Dependencies all met for <TaskInstance: sample_data_etl_v3.sample_data_precheck scheduled__2023-01-17T07:00:00+00:00 [queued]>
[2023-01-17T11:55:47.104+0000] {taskinstance.py:1087} INFO - Dependencies all met for <TaskInstance: sample_data_etl_v3.sample_data_precheck scheduled__2023-01-17T07:00:00+00:00 [queued]>
[2023-01-17T11:55:47.104+0000] {taskinstance.py:1283} INFO - 
--------------------------------------------------------------------------------
[2023-01-17T11:55:47.104+0000] {taskinstance.py:1284} INFO - Starting attempt 2 of 2
[2023-01-17T11:55:47.148+0000] {taskinstance.py:1285} INFO - 
--------------------------------------------------------------------------------
[2023-01-17T11:55:47.228+0000] {taskinstance.py:1304} INFO - Executing <Task(MsSqlOperator): sample_data_precheck> on 2023-01-17 07:00:00+00:00
[2023-01-17T11:55:47.232+0000] {standard_task_runner.py:55} INFO - Started process 2644 to run task
[2023-01-17T11:55:47.234+0000] {standard_task_runner.py:82} INFO - Running: ['***', 'tasks', 'run', 'sample_data_etl_v3', 'sample_data_precheck', 'scheduled__2023-01-17T07:00:00+00:00', '--job-id', '435', '--raw', '--subdir', 'DAGS_FOLDER/test_table_insert.py', '--cfg-path', '/tmp/tmp8qmzi1vr']
[2023-01-17T11:55:47.236+0000] {standard_task_runner.py:83} INFO - Job 435: Subtask sample_data_precheck
[2023-01-17T11:55:47.420+0000] {task_command.py:389} INFO - Running <TaskInstance: sample_data_etl_v3.sample_data_precheck scheduled__2023-01-17T07:00:00+00:00 [running]> on host c7f1bfaaf748
[2023-01-17T11:55:47.641+0000] {taskinstance.py:1513} INFO - Exporting the following env vars:
AIRFLOW_CTX_DAG_EMAIL=StepanovLM@eurosib.biz
AIRFLOW_CTX_DAG_OWNER=***
AIRFLOW_CTX_DAG_ID=sample_data_etl_v3
AIRFLOW_CTX_TASK_ID=sample_data_precheck
AIRFLOW_CTX_EXECUTION_DATE=2023-01-17T07:00:00+00:00
AIRFLOW_CTX_TRY_NUMBER=2
AIRFLOW_CTX_DAG_RUN_ID=scheduled__2023-01-17T07:00:00+00:00
[2023-01-17T11:55:47.642+0000] {sql.py:253} INFO - Executing: use CarInfo go select getDate() as nowdate
[2023-01-17T11:55:47.652+0000] {base.py:73} INFO - Using connection ID 'tsxdvp' for task execution.
[2023-01-17T11:55:47.929+0000] {base.py:73} INFO - Using connection ID 'tsxdvp' for task execution.
[2023-01-17T11:55:48.196+0000] {sql.py:364} INFO - Running statement: use CarInfo go select getDate() as nowdate, parameters: None
[2023-01-17T11:55:48.204+0000] {taskinstance.py:1772} ERROR - Task failed with exception
Traceback (most recent call last):
  File "src/pymssql/_pymssql.pyx", line 459, in pymssql._pymssql.Cursor.execute
  File "src/pymssql/_mssql.pyx", line 1087, in pymssql._mssql.MSSQLConnection.execute_query
  File "src/pymssql/_mssql.pyx", line 1118, in pymssql._mssql.MSSQLConnection.execute_query
  File "src/pymssql/_mssql.pyx", line 1251, in pymssql._mssql.MSSQLConnection.format_and_run_query
  File "src/pymssql/_mssql.pyx", line 1789, in pymssql._mssql.check_cancel_and_raise
  File "src/pymssql/_mssql.pyx", line 1835, in pymssql._mssql.raise_MSSQLDatabaseException
pymssql._mssql.MSSQLDatabaseException: (102, b"Incorrect syntax near 'go'.DB-Lib error message 20018, severity 15:\nGeneral SQL Server error: Check messages from the SQL Server\n")

During handling of the above exception, another exception occurred:

Traceback (most recent call last):
  File "/home/airflow/.local/lib/python3.7/site-packages/airflow/providers/common/sql/operators/sql.py", line 261, in execute
    return_last=self.return_last,
  File "/home/airflow/.local/lib/python3.7/site-packages/airflow/providers/common/sql/hooks/sql.py", line 338, in run
    self._run_command(cur, sql_statement, parameters)
  File "/home/airflow/.local/lib/python3.7/site-packages/airflow/providers/common/sql/hooks/sql.py", line 369, in _run_command
    cur.execute(sql_statement)
  File "src/pymssql/_pymssql.pyx", line 476, in pymssql._pymssql.Cursor.execute
pymssql._pymssql.ProgrammingError: (102, b"Incorrect syntax near 'go'.DB-Lib error message 20018, severity 15:\nGeneral SQL Server error: Check messages from the SQL Server\n")
[2023-01-17T11:55:48.213+0000] {taskinstance.py:1327} INFO - Marking task as FAILED. dag_id=sample_data_etl_v3, task_id=sample_data_precheck, execution_date=20230117T070000, start_date=20230117T115547, end_date=20230117T115548
[2023-01-17T11:55:48.233+0000] {logging_mixin.py:137} WARNING - /home/***/.local/lib/python3.7/site-packages/***/utils/email.py:120 RemovedInAirflow3Warning: Fetching SMTP credentials from configuration variables will be deprecated in a future release. Please set credentials using a connection instead.
[2023-01-17T11:55:48.233+0000] {configuration.py:635} WARNING - section/key [smtp/smtp_user] not found in config
[2023-01-17T11:55:48.234+0000] {email.py:229} INFO - Email alerting: attempt 1
[2023-01-17T11:55:48.241+0000] {configuration.py:635} WARNING - section/key [smtp/smtp_user] not found in config
[2023-01-17T11:55:48.242+0000] {email.py:229} INFO - Email alerting: attempt 1
[2023-01-17T11:55:48.242+0000] {taskinstance.py:1835} ERROR - Failed to send email to: ['StepanovLM@eurosib.biz']
Traceback (most recent call last):
  File "src/pymssql/_pymssql.pyx", line 459, in pymssql._pymssql.Cursor.execute
  File "src/pymssql/_mssql.pyx", line 1087, in pymssql._mssql.MSSQLConnection.execute_query
  File "src/pymssql/_mssql.pyx", line 1118, in pymssql._mssql.MSSQLConnection.execute_query
  File "src/pymssql/_mssql.pyx", line 1251, in pymssql._mssql.MSSQLConnection.format_and_run_query
  File "src/pymssql/_mssql.pyx", line 1789, in pymssql._mssql.check_cancel_and_raise
  File "src/pymssql/_mssql.pyx", line 1835, in pymssql._mssql.raise_MSSQLDatabaseException
pymssql._mssql.MSSQLDatabaseException: (102, b"Incorrect syntax near 'go'.DB-Lib error message 20018, severity 15:\nGeneral SQL Server error: Check messages from the SQL Server\n")

During handling of the above exception, another exception occurred:

Traceback (most recent call last):
  File "/home/airflow/.local/lib/python3.7/site-packages/airflow/models/taskinstance.py", line 1378, in _run_raw_task
    self._execute_task_with_callbacks(context, test_mode)
  File "/home/airflow/.local/lib/python3.7/site-packages/airflow/models/taskinstance.py", line 1524, in _execute_task_with_callbacks
    result = self._execute_task(context, task_orig)
  File "/home/airflow/.local/lib/python3.7/site-packages/airflow/models/taskinstance.py", line 1585, in _execute_task
    result = execute_callable(context=context)
  File "/home/airflow/.local/lib/python3.7/site-packages/airflow/providers/common/sql/operators/sql.py", line 261, in execute
    return_last=self.return_last,
  File "/home/airflow/.local/lib/python3.7/site-packages/airflow/providers/common/sql/hooks/sql.py", line 338, in run
    self._run_command(cur, sql_statement, parameters)
  File "/home/airflow/.local/lib/python3.7/site-packages/airflow/providers/common/sql/hooks/sql.py", line 369, in _run_command
    cur.execute(sql_statement)
  File "src/pymssql/_pymssql.pyx", line 476, in pymssql._pymssql.Cursor.execute
pymssql._pymssql.ProgrammingError: (102, b"Incorrect syntax near 'go'.DB-Lib error message 20018, severity 15:\nGeneral SQL Server error: Check messages from the SQL Server\n")

During handling of the above exception, another exception occurred:

Traceback (most recent call last):
  File "/home/airflow/.local/lib/python3.7/site-packages/airflow/models/taskinstance.py", line 2235, in email_alert
    send_email(task.email, subject, html_content)
  File "/home/airflow/.local/lib/python3.7/site-packages/airflow/utils/email.py", line 72, in send_email
    **kwargs,
  File "/home/airflow/.local/lib/python3.7/site-packages/airflow/utils/email.py", line 120, in send_email_smtp
    send_mime_email(e_from=mail_from, e_to=recipients, mime_msg=msg, conn_id=conn_id, dryrun=dryrun)
  File "/home/airflow/.local/lib/python3.7/site-packages/airflow/utils/email.py", line 231, in send_mime_email
    smtp_conn = _get_smtp_connection(smtp_host, smtp_port, smtp_timeout, smtp_ssl)
  File "/home/airflow/.local/lib/python3.7/site-packages/airflow/utils/email.py", line 265, in _get_smtp_connection
    else smtplib.SMTP(host=host, port=port, timeout=timeout)
  File "/usr/local/lib/python3.7/smtplib.py", line 251, in __init__
    (code, msg) = self.connect(host, port)
  File "/usr/local/lib/python3.7/smtplib.py", line 336, in connect
    self.sock = self._get_socket(host, port, self.timeout)
  File "/usr/local/lib/python3.7/smtplib.py", line 307, in _get_socket
    self.source_address)
  File "/usr/local/lib/python3.7/socket.py", line 728, in create_connection
    raise err
  File "/usr/local/lib/python3.7/socket.py", line 716, in create_connection
    sock.connect(sa)
OSError: [Errno 99] Cannot assign requested address

During handling of the above exception, another exception occurred:

Traceback (most recent call last):
  File "/home/airflow/.local/lib/python3.7/site-packages/airflow/models/taskinstance.py", line 1833, in handle_failure
    self.email_alert(error, task)
  File "/home/airflow/.local/lib/python3.7/site-packages/airflow/models/taskinstance.py", line 2237, in email_alert
    send_email(task.email, subject, html_content_err)
  File "/home/airflow/.local/lib/python3.7/site-packages/airflow/utils/email.py", line 72, in send_email
    **kwargs,
  File "/home/airflow/.local/lib/python3.7/site-packages/airflow/utils/email.py", line 120, in send_email_smtp
    send_mime_email(e_from=mail_from, e_to=recipients, mime_msg=msg, conn_id=conn_id, dryrun=dryrun)
  File "/home/airflow/.local/lib/python3.7/site-packages/airflow/utils/email.py", line 231, in send_mime_email
    smtp_conn = _get_smtp_connection(smtp_host, smtp_port, smtp_timeout, smtp_ssl)
  File "/home/airflow/.local/lib/python3.7/site-packages/airflow/utils/email.py", line 265, in _get_smtp_connection
    else smtplib.SMTP(host=host, port=port, timeout=timeout)
  File "/usr/local/lib/python3.7/smtplib.py", line 251, in __init__
    (code, msg) = self.connect(host, port)
  File "/usr/local/lib/python3.7/smtplib.py", line 336, in connect
    self.sock = self._get_socket(host, port, self.timeout)
  File "/usr/local/lib/python3.7/smtplib.py", line 307, in _get_socket
    self.source_address)
  File "/usr/local/lib/python3.7/socket.py", line 728, in create_connection
    raise err
  File "/usr/local/lib/python3.7/socket.py", line 716, in create_connection
    sock.connect(sa)
OSError: [Errno 99] Cannot assign requested address
[2023-01-17T11:55:48.863+0000] {standard_task_runner.py:105} ERROR - Failed to execute job 435 for task sample_data_precheck ((102, b"Incorrect syntax near 'go'.DB-Lib error message 20018, severity 15:\nGeneral SQL Server error: Check messages from the SQL Server\n"); 2644)
[2023-01-17T11:55:48.891+0000] {local_task_job.py:159} INFO - Task exited with return code 1
[2023-01-17T11:55:48.916+0000] {taskinstance.py:2582} INFO - 0 downstream tasks scheduled from follow-on schedule check
